Workbook

Sheet README
A1: Workbook type | B1: Development Method — Reference Values
A2: Run ID | B2: 2e32e596-6d90-4aea-ad4e-fb637f8b4696
A3: Generated at | B3: 2026-10-14T19:10:54.500847+00:00
A4: Cutoff | B4: 2022-12
A5: Basis | B5: month
A6: Concept | B6: Loss Incurred
A7: Level 1 | B7: Synthetic
A8: Level 2 | B8: Portfolio
A9: Level 3 | B9: Auto
A10: Source | B10: synthetic_monthly_multiconcept_database.csv (fully synthetic, seed=42)
A11: Units | B11: Unspecified
A12: Method | B12: Development Method
... A15: Schema version | B15: 1.0
A17: Additional development | B17: =Ultimate - Current Incurred. NOT equivalent to total IBNR without additional data. -> 0
A19: Windows validation | B19: Open in Excel, press Ctrl+Alt+F9, verify Formula Calculations column E matches Python Reference Ultimate.

Sheet Cumulative
A1: accident_period | B1: 0 | C1: 1 | D1: 2 | E1: 3 | F1: 4 | G1: 5 | H1: 6 | I1: 7 | J1: 8 | K1: 9 | L1: 10 | M1: 11 | N1: 12 | O1: 13 | P1: 14 | Q1: 15 | R1: 16 | S1: 17 | T1: 18 | U1: 19 | V1: 20 | W1: 21 | X1: 22 | Y1: 23 | Z1: 24 | AA1: 25 | AB1: 26 | AC1: 27 | AD1: 28 | AE1: 29 | AF1: 30 | AG1: 31 | AH1: 32 | AI1: 33 | AJ1: 34 | AK1: 35 | AL1: 36 | AM1: 37 | AN1: 38 | AO1: 39 | AP1: 40 | AQ1: 41 | AR1: 42 | AS1: 43 | AT1: 44 | AU1: 45 | AV1: 46 | AW1: 47 | AX1: 48 | AY1: 49 | AZ1: 50 | BA1: 51 | BB1: 52 | BC1: 53 | BD1: 54 | BE1: 55 | BF1: 56 | BG1: 57 | BH1: 58 | BI1: 59 | BJ1: 60 | BK1: 61 | BL1: 62 | BM1: 63 | BN1: 64 | BO1: 65 | BP1: 66 | BQ1: 67 | BR1: 68 | BS1: 69 | BT1: 70 | BU1: 71 | BV1: 72 | BW1: 73 | BX1: 74 | BY1: 75 | BZ1: 76 | CA1: 77 | CB1: 78 | CC1: 79 | CD1: 80 | CE1: 81 | CF1: 82 | CG1: 83
A2: 2016-01 | B2: 37434.057 | C2: 42532.107 | D2: 48179.606 | E2: 54396.382 | F2: 61192.412 | G2: 68565.45 | H2: 76498.856 | I2: 84959.905 | J2: 93898.829 | K2: 103248.84 | L2: 112927.32 | M2: 122838.17 | N2: 132875.36 | O2: 142927.29 | P2: 152881.73 | Q2: 162630.73 | R2: 172075.22 | S2: 181128.78 | T2: 189720.32 | U2: 197795.56 | V2: 205317.38 | W2: 212265.08 | X2: 218632.84 | Y2: 224427.67 | Z2: 229667.04 | AA2: 234376.52 | AB2: 238587.44 | AC2: 242334.89 | AD2: 245655.9 | AE2: 248588.09 | AF2: 251168.47 | AG2: 253432.71 | AH2: 255414.51 | AI2: 257145.25 | AJ2: 258653.8 | AK2: 259966.47 | AL2: 261107 | AM2: 262096.72 | AN2: 262954.6 | AO2: 263697.5 | AP2: 264340.29 | AQ2: 264896.05 | AR2: 265376.28 | AS2: 265791.01 | AT2: 266149.01 | AU2: 266457.92 | AV2: 266724.38 | AW2: 266954.15 | AX2: 267152.22 | AY2: 267322.95 | AZ2: 267470.07 | BA2: 267596.82 | BB2: 267706.02 | BC2: 267800.08 | BD2: 267881.08 | BE2: 267950.85 | BF2: 268010.92 | BG2: 268062.65 | BH2: 268107.19 | BI2: 268145.54 | BJ2: 268178.56 | BK2: 268206.98 | BL2: 268231.45 | BM2: 268252.51 | BN2: 268270.64 | BO2: 268286.25 | BP2: 268299.69 | BQ2: 268311.25 | BR2: 268321.21 | BS2: 268329.78 | BT2: 268337.15 | BU2: 268343.5 | BV2: 268348.97 | BW2: 268353.67 | BX2: 268357.72 | BY2: 268361.2 | BZ2: 268364.2 | CA2: 268366.79 | CB2: 268369.01 | CC2: 268370.92 | CD2: 268372.57 | CE2: 268373.98 | CF2: 268375.2 | CG2: 268376.25
A3: 2016-02 | B3: 88815.648 | C3: 101103.48 | D3: 114770.43 | E3: 129882.04 | F3: 146482.58 | G3: 164588.87 | H3: 184184.15 | I3: 205212.81 | J3: 227576.43 | K3: 251132.13 | L3: 275693.4 | M3: 301034.19 | N3: 326896.02 | O3: 352997.88 | P3: 379048.13 | Q3: 404757.45 | R3: 429851.48 | S3: 454082.17 | T3: 477236.76 | U3: 499143.83 | V3: 519676.2 | W3: 538750.87 | X3: 556326.45 | Y3: 572398.69 | Z3: 586994.78 | AA3: 600167.22 | AB3: 611987.57 | AC3: 622540.71 | AD3: 631919.71 | AE3: 640221.56 | AF3: 647543.71 | AG3: 653981.38 | AH3: 659625.72 | AI3: 664562.46 | AJ3: 668871.1 | AK3: 672624.57 | AL3: 675889.11 | AM3: 678724.4 | AN3: 681183.88 | AO3: 683315.09 | AP3: 685160.15 | AQ3: 686756.2 | AR3: 688135.91 | AS3: 689327.88 | AT3: 690357.12 | AU3: 691245.47 | AV3: 692011.91 | AW3: 692672.95 | AX3: 693242.93 | AY3: 693734.26 | AZ3: 694157.72 | BA3: 694522.6 | BB3: 694836.97 | BC3: 695107.77 | BD3: 695341.03 | BE3: 695541.92 | BF3: 695714.92 | BG3: 695863.89 | BH3: 695992.16 | BI3: 696102.6 | BJ3: 696197.69 | BK3: 696279.55 | BL3: 696350.03 | BM3: 696410.7 | BN3: 696462.92 | BO3: 696507.88 | BP3: 696546.58 | BQ3: 696579.9 | BR3: 696608.57 | BS3: 696633.26 | BT3: 696654.5 | BU3: 696672.79 | BV3: 696688.53 | BW3: 696702.08 | BX3: 696713.75 | BY3: 696723.79 | BZ3: 696732.43 | CA3: 696739.86 | CB3: 696746.26 | CC3: 696751.77 | CD3: 696756.52 | CE3: 696760.6 | CF3: 696764.11
A4: 2016-03 | B4: 154494.7 | C4: 175438.96 | D4: 198613.8 | E4: 224092.27 | F4: 251905.93 | G4: 282035.34 | H4: 314401.63 | I4: 348860.14 | J4: 385197.29 | K4: 423131.46 | L4: 462318.69 | M4: 502363.2 | N4: 542832.25 | O4: 583274.37 | P4: 623239.28 | Q4: 662297.74 | R4: 700059.4 | S4: 736187.22 | T4: 770407.48 | U4: 802514.78 | V4: 832372.52 | W4: 859909.25 | X4: 885112.05 | Y4: 908017.89 | Z4: 928704.11 | AA4: 947278.76 | AB4: 963871.49 | AC4: 978625.59 | AD4: 991691.08 | AE4: 1003219.3 | AF4: 1013358.5 | AG4: 1022250.9 | AH4: 1030030.6 | AI4: 1036822.1 | AJ4: 1042739.8 | AK4: 1047887.5 | AL4: 1052359 | AM4: 1056238.4 | AN4: 1059600.4 | AO4: 1062511.2 | AP4: 1065029.5 | AQ4: 1067206.5 | AR4: 1069087.5 | AS4: 1070711.7 | AT4: 1072113.7 | AU4: 1073323.3 | AV4: 1074366.7 | AW4: 1075266.3 | AX4: 1076041.8 | AY4: 1076710.2 | AZ4: 1077286.2 | BA4: 1077782.4 | BB4: 1078209.9 | BC4: 1078578.1 | BD4: 1078895.2 | BE4: 1079168.3 | BF4: 1079403.4 | BG4: 1079605.9 | BH4: 1079780.3 | BI4: 1079930.4 | BJ4: 1080059.6 | BK4: 1080170.9 | BL4: 1080266.6 | BM4: 1080349.1 | BN4: 1080420.1 | BO4: 1080481.1 | BP4: 1080533.7 | BQ4: 1080579 | BR4: 1080618 | BS4: 1080651.5 | BT4: 1080680.4 | BU4: 1080705.2 | BV4: 1080726.6 | BW4: 1080745 | BX4: 1080760.9 | BY4: 1080774.5 | BZ4: 1080786.3 | CA4: 1080796.4 | CB4: 1080805.1 | CC4: 1080812.6 | CD4: 1080819 | CE4: 1080824.5
A5: 2016-04 | B5: 103617.09 | C5: 117427.08 | D5: 132643.16 | E5: 149293.84 | F5: 167378.14 | G5: 186860.09 | H5: 207664.3 | I5: 229673.33 | J5: 252727.39 | K5: 276626.78 | L5: 301137.45 | M5: 325999.29 | N5: 350936.82 | O5: 375671.16 | P5: 399932.46 | Q5: 423471.34 | R5: 446068.66 | S5: 467542.5 | T5: 487752.35 | U5: 506600.27 | V5: 524029.39 | W5: 540020.4 | X5: 554586.58 | Y5: 567768 | Z5: 579625.58 | AA5: 590235.36 | AB5: 599683.29 | AC5: 608060.78 | AD5: 615461.07 | AE5: 621976.32 | AF5: 627695.53 | AG5: 632702.98 | AH5: 637077.36 | AI5: 640891.15 | AJ5: 644210.46 | AK5: 647095.08 | AL5: 649598.65 | AM5: 651769.07 | AN5: 653648.81 | AO5: 655275.42 | AP5: 656681.95 | AQ5: 657897.41 | AR5: 658947.17 | AS5: 659853.4 | AT5: 660635.39 | AU5: 661309.94 | AV5: 661891.64 | AW5: 662393.14 | AX5: 662825.38 | AY5: 663197.87 | AZ5: 663518.82 | BA5: 663795.3 | BB5: 664033.46 | BC5: 664238.58 | BD5: 664415.23 | BE5: 664567.35 | BF5: 664698.34 | BG5: 664811.12 | BH5: 664908.22 | BI5: 664991.83 | BJ5: 665063.8 | BK5: 665125.76 | BL5: 665179.1 | BM5: 665225.01 | BN5: 665264.54 | BO5: 665298.56 | BP5: 665327.85 | BQ5: 665353.06 | BR5: 665374.76 | BS5: 665393.44 | BT5: 665409.51 | BU5: 665423.35 | BV5: 665435.26 | BW5: 665445.52 | BX5: 665454.34 | BY5: 665461.94 | BZ5: 665468.47 | CA5: 665474.1 | CB5: 665478.94 | CC5: 665483.11 | CD5: 665486.7
A6: 2016-05 | B6: 45657.879 | C6: 51793.049 | D6: 58566.607 | E6: 65995.333 | F6: 74083.323 | G6: 82819.374 | H6: 92174.78 | I6: 102101.83 | J6: 112533.28 | K6: 123383.1 | L6: 134548.56 | M6: 145913.65 | N6: 157353.65 | O6: 168740.56 | P6: 179948.69 | Q6: 190860.21 | R6: 201369.82 | S6: 211388.45 | T6: 220845.56 | U6: 229690.1 | V6: 237890.2 | W6: 245431.8 | X6: 252316.55 | Y6: 258559.26 | Z6: 264185.16 | AA6: 269227.21 | AB6: 273723.62 | AC6: 277715.75 | AD6: 281246.23 | AE6: 284357.62 | AF6: 287091.27 | AG6: 289486.58 | AH6: 291580.49 | AI6: 293407.14 | AJ6: 294997.77 | AK6: 296380.72 | AL6: 297581.46 | AM6: 298622.77 | AN6: 299524.88 | AO6: 300305.71 | AP6: 300981.05 | AQ6: 301564.75 | AR6: 302068.97 | AS6: 302504.3 | AT6: 302880 | AU6: 303204.12 | AV6: 303483.64 | AW6: 303724.65 | AX6: 303932.39 | AY6: 304111.42 | AZ6: 304265.68 | BA6: 304398.58 | BB6: 304513.06 | BC6: 304611.67 | BD6: 304696.59 | BE6: 304769.72 | BF6: 304832.69 | BG6: 304886.91 | BH6: 304933.59 | BI6: 304973.79 | BJ6: 305008.39 | BK6: 305038.18 | BL6: 305063.82 | BM6: 305085.9 | BN6: 305104.9 | BO6: 305121.26 | BP6: 305135.34 | BQ6: 305147.46 | BR6: 305157.89 | BS6: 305166.87 | BT6: 305174.6 | BU6: 305181.26 | BV6: 305186.98 | BW6: 305191.91 | BX6: 305196.16 | BY6: 305199.81 | BZ6: 305202.95 | CA6: 305205.66 | CB6: 305207.99 | CC6: 305209.99
A7: 2016-06 | B7: 52017.537 | C7: 59184.236 | D7: 67146.75 | E7: 75940.484 | F7: 85588.039 | G7: 96095.635 | H7: 107449.7 | I7: 119613.95 | J7: 132527.38 | K7: 146103.52 | L7: 160231.29 | M7: 174777.67 | N7: 189592.05 | O7: 204512.18 | P7: 219371.11 | Q7: 234004.64 | R7: 248258.39 | S7: 261994.12 | T7: 275094.57 | U7: 287466.5 | V7: 299042.1 | W7: 309778.63 | X7: 319656.67 | Y7: 328677.47 | Z7: 336859.6 | AA7: 344235.37 | AB7: 350847.37 | AC7: 356745.19 | AD7: 361982.6 | AE7: 366615.2 | AF7: 370698.52 | AG7: 374286.61 | AH7: 377430.99 | AI7: 380180.01 | AJ7: 382578.37 | AK7: 384667.03 | AL7: 386483.1 | AM7: 388059.99 | AN7: 389427.58 | AO7: 390612.41 | AP7: 391638 | AQ7: 392525.05 | AR7: 393291.76 | AS7: 393954.08 | AT7: 394525.94 | AU7: 395019.47 | AV7: 395445.24 | AW7: 395812.45 | AX7: 396129.05 | AY7: 396401.96 | AZ7: 396637.15 | BA7: 396839.81 | BB7: 397014.41 | BC7: 397164.8 | BD7: 397294.34 | BE7: 397405.91 | BF7: 397501.98 | BG7: 397584.71 | BH7: 397655.95 | BI7: 397717.28 | BJ7: 397770.08 | BK7: 397815.54 | BL7: 397854.68 | BM7: 397888.37 | BN7: 397917.37 | BO7: 397942.34 | BP7: 397963.83 | BQ7: 397982.33 | BR7: 397998.25 | BS7: 398011.96 | BT7: 398023.75 | BU7: 398033.91 | BV7: 398042.65 | BW7: 398050.18 | BX7: 398056.65 | BY7: 398062.23 | BZ7: 398067.02 | CA7: 398071.15 | CB7: 398074.71
A8: 2016-07 | B8: 53298.34 | C8: 60534.715 | D8: 68544.813 | E8: 77354.826 | F8: 86976.726 | G8: 97404.948 | H8: 108613.42 | I8: 120553.32 | J8: 133151.85 | K8: 146312.53 | L8: 159917 | M8: 173828.6 | N8: 187897.46 | O8: 201966.8 | P8: 215879.8 | Q8: 229486.53 | R8: 242650.23 | S8: 255252.45 | T8: 267196.52 | U8: 278409.55 | V8: 288842.54 | W8: 298469.3 | X8: 307284.16 | Y8: 315298.98 | Z8: 322539.88 | AA8: 329043.88 | AB8: 334855.67 | AC8: 340024.86 | AD8: 344603.54 | AE8: 348644.35 | AF8: 352198.97 | AG8: 355317.01 | AH8: 358045.28 | AI8: 360427.3 | AJ8: 362503.05 | AK8: 364308.9 | AL8: 365877.68 | AM8: 367238.8 | AN8: 368418.47 | AO8: 369439.9 | AP8: 370323.6 | AQ8: 371087.6 | AR8: 371747.71 | AS8: 372317.76 | AT8: 372809.8 | AU8: 373234.35 | AV8: 373600.54 | AW8: 373916.3 | AX8: 374188.5 | AY8: 374423.1 | AZ8: 374625.27 | BA8: 374799.44 | BB8: 374949.49 | BC8: 375078.73 | BD8: 375190.04 | BE8: 375285.9 | BF8: 375368.44 | BG8: 375439.52 | BH8: 375500.72 | BI8: 375553.41 | BJ8: 375598.77 | BK8: 375637.82 | BL8: 375671.44 | BM8: 375700.38 | BN8: 375725.29 | BO8: 375746.74 | BP8: 375765.2 | BQ8: 375781.09 | BR8: 375794.77 | BS8: 375806.54 | BT8: 375816.68 | BU8: 375825.4 | BV8: 375832.91 | BW8: 375839.37 | BX8: 375844.93 | BY8: 375849.72 | BZ8: 375853.84 | CA8: 375857.39
A9: 2016-08 | B9: 26669.238 | C9: 30319.144 | D9: 34367.459 | E9: 38829.98 | F9: 43715.67 | G9: 49024.897 | H9: 54747.803 | I9: 60862.979 | J9: 67336.634 | K9: 74122.447 | L9: 81162.248 | M9: 88387.577 | N9: 95722.097 | O9: 103084.68 | P9: 110392.97 | Q9: 117566.98 | R9: 124532.61 | S9: 131224.44 | T9: 137587.98 | U9: 143580.86 | V9: 149173.32 | W9: 154347.74 | X9: 159097.71 | Y9: 163426.52 | Z9: 167345.52 | AA9: 170872.31 | AB9: 174029.08 | AC9: 176841.05 | AD9: 179335.13 | AE9: 181538.83 | AF9: 183479.4 | AG9: 185183.2 | AH9: 186675.21 | AI9: 187978.79 | AJ9: 189115.45 | AK9: 190104.85 | AL9: 190964.77 | AM9: 191711.16 | AN9: 192358.27 | AO9: 192918.75 | AP9: 193403.78 | AQ9: 193823.21 | AR9: 194185.67 | AS9: 194498.74 | AT9: 194769 | AU9: 195002.22 | AV9: 195203.41 | AW9: 195376.9 | AX9: 195526.48 | AY9: 195655.4 | AZ9: 195766.5 | BA9: 195862.23 | BB9: 195944.7 | BC9: 196015.73 | BD9: 196076.91 | BE9: 196129.61 | BF9: 196174.98 | BG9: 196214.05 | BH9: 196247.69 | BI9: 196276.66 | BJ9: 196301.59 | BK9: 196323.06 | BL9: 196341.54 | BM9: 196357.45 | BN9: 196371.15 | BO9: 196382.94 | BP9: 196393.09 | BQ9: 196401.82 | BR9: 196409.34 | BS9: 196415.82 | BT9: 196421.39 | BU9: 196426.18 | BV9: 196430.31 | BW9: 196433.87 | BX9: 196436.92 | BY9: 196439.56 | BZ9: 196441.82
A10: 2016-09 | B10: 24635.962 | C10: 28032.906 | D10: 31807.835 | E10: 35977.786 | F10: 40553.762 | G10: 45539.036 | H10: 50927.516 | I10: 56702.346 | J10: 62834.933 | K10: 69284.566 | L10: 75998.8 | M10: 82914.675 | N10: 89960.787 | O10: 97060.07 | P10: 104133.11 | Q10: 111101.64 | R10: 117892.01 | S10: 124438.09 | T10: 130683.7 | U10: 136584.04 | V10: 142106.4 | W10: 147230.03 | X10: 151945.3 | Y10: 156252.48 | Z10: 160160.14 | AA10: 163683.44 | AB10: 166842.5 | AC10: 169660.82 | AD10: 172163.94 | AE10: 174378.3 | AF10: 176330.35 | AG10: 178045.82 | AH10: 179549.3 | AI10: 180863.84 | AJ10: 182010.78 | AK10: 183009.67 | AL10: 183878.25 | AM10: 184632.47 | AN10: 185286.61 | AO10: 185853.35 | AP10: 186343.94 | AQ10: 186768.27 | AR10: 187135.04 | AS10: 187451.88 | AT10: 187725.45 | AU10: 187961.55 | AV10: 188165.24 | AW10: 188340.91 | AX10: 188492.38 | AY10: 188622.94 | AZ10: 188735.46 | BA10: 188832.42 | BB10: 188915.95 | BC10: 188987.9 | BD10: 189049.88 | BE10: 189103.25 | BF10: 189149.22 | BG10: 189188.8 | BH10: 189222.88 | BI10: 189252.22 | BJ10: 189277.48 | BK10: 189299.23 | BL10: 189317.96 | BM10: 189334.08 | BN10: 189347.95 | BO10: 189359.9 | BP10: 189370.18 | BQ10: 189379.03 | BR10: 189386.65 | BS10: 189393.21 | BT10: 189398.85 | BU10: 189403.71 | BV10: 189407.89 | BW10: 189411.49 | BX10: 189414.59 | BY10: 189417.26
A11: 2016-10 | B11: 57660.958 | C11: 65416.815 | D11: 73981.846 | E11: 83377.919 | F11: 93610.936 | G11: 104667.5 | H11: 116512.11 | I11: 129085.17 | J11: 142302.31 | K11: 156055.25 | L11: 170214.35 | M11: 184632.91 | N11: 199152.98 | O11: 213612.07 | P11: 227850.43 | Q11: 241717.96 | R11: 255080.27 | S11: 267823.43 | T11: 279856.94 | U11: 291115.02 | V11: 301556.26 | W11: 311161.98 | X11: 319933.55 | Y11: 327889.16 | Z11: 335060.38 | AA11: 341488.7 | AB11: 347222.45 | AC11: 352313.97 | AD11: 356817.38 | AE11: 360786.72 | AF11: 364274.57 | AG11: 367331.04 | AH11: 370003.13 | AI11: 372334.35 | AJ11: 374364.51 | AK11: 376129.69 | AL11: 377662.37 | AM11: 378991.61 | AN11: 380143.21 | AO11: 381140.02 | AP11: 382002.17 | AQ11: 382747.37 | AR11: 383391.09 | AS11: 383946.89 | AT11: 384426.56 | AU11: 384840.38 | AV11: 385197.27 | AW11: 385504.98 | AX11: 385770.22 | AY11: 385998.81 | AZ11: 386195.77 | BA11: 386365.46 | BB11: 386511.64 | BC11: 386637.54 | BD11: 386745.97 | BE11: 386839.34 | BF11: 386919.75 | BG11: 386988.98 | BH11: 387048.58 | BI11: 387099.9 | BJ11: 387144.09 | BK11: 387182.12 | BL11: 387214.87 | BM11: 387243.05 | BN11: 387267.32 | BO11: 387288.21 | BP11: 387306.19 | BQ11: 387321.66 | BR11: 387334.98 | BS11: 387346.45 | BT11: 387356.32 | BU11: 387364.82 | BV11: 387372.13 | BW11: 387378.42 | BX11: 387383.84
A12: 2016-11 | B12: 40897.13 | C12: 46546.992 | D12: 52828.585 | E12: 59771.252 | F12: 67394.453 | G12: 75704.91 | H12: 84693.848 | I12: 94334.608 | J12: 104580.92 | K12: 115366.19 | L12: 126604.01 | M12: 138190.07 | N12: 150005.56 | O12: 161921.7 | P12: 173805.27 | Q12: 185524.51 | R12: 196954.84 | S12: 207984.02 | T12: 218516.14 | U12: 228474.3 | V12: 237801.83 | W12: 246462.18 | X12: 254437.67 | Y12: 261727.41 | Z12: 268344.69 | AA12: 274314.15 | AB12: 279668.92 | AC12: 284448.09 | AD12: 288694.3 | AE12: 292451.89 | AF12: 295765.29 | AG12: 298677.88 | AH12: 301231.09 | AI12: 303463.87 | AJ12: 305412.32 | AK12: 307109.52 | AL12: 308585.48 | AM12: 309867.27 | AN12: 310979.06 | AO12: 311942.4 | AP12: 312776.35 | AQ12: 313497.72 | AR12: 314121.27 | AS12: 314659.96 | AT12: 315125.09 | AU12: 315526.54 | AV12: 315872.89 | AW12: 316171.6 | AX12: 316429.16 | AY12: 316651.18 | AZ12: 316842.53 | BA12: 317007.4 | BB12: 317149.45 | BC12: 317271.81 | BD12: 317377.21 | BE12: 317467.98 | BF12: 317546.15 | BG12: 317613.46 | BH12: 317671.42 | BI12: 317721.32 | BJ12: 317764.28 | BK12: 317801.27 | BL12: 317833.11 | BM12: 317860.52 | BN12: 317884.12 | BO12: 317904.44 | BP12: 317921.92 | BQ12: 317936.97 | BR12: 317949.93 | BS12: 317961.08 | BT12: 317970.68 | BU12: 317978.95 | BV12: 317986.06 | BW12: 317992.18
A13: 2016-12 | B13: 43275.302 | C13: 49203.171 | D13: 55779.593 | E13: 63030.704 | F13: 70971.603 | G13: 79603.483 | H13: 88910.958 | I13: 98859.873 | J13: 109395.91 | K13: 120444.31 | L13: 131910.92 | M13: 143684.67 | N13: 155641.47 | O13: 167649.24 | P13: 179573.61 | Q13: 191283.9 | R13: 202658.78 | S13: 213590.96 | T13: 223990.83 | U13: 233788.52 | V13: 242934.68 | W13: 251399.86 | X13: 259172.93 | Y13: 266258.7 | Z13: 272675.21 | AA13: 278450.84 | AB13: 283621.53 | AC13: 288228.26 | AD13: 292314.85 | AE13: 295926.14 | AF13: 299106.63 | AG13: 301899.35 | AH13: 304345.17 | AI13: 306482.27 | AJ13: 308345.86 | AK13: 309968.12 | AL13: 311378.13 | AM13: 312602.06 | AN13: 313663.23 | AO13: 314582.38 | AP13: 315377.82 | AQ13: 316065.69 | AR13: 316660.15 | AS13: 317173.61 | AT13: 317616.88 | AU13: 317999.39 | AV13: 318329.37 | AW13: 318613.93 | AX13: 318859.26 | AY13: 319070.72 | AZ13: 319252.95 | BA13: 319409.97 | BB13: 319545.24 | BC13: 319661.75 | BD13: 319762.11 | BE13: 319848.54 | BF13: 319922.96 | BG13: 319987.05 | BH13: 320042.23 | BI13: 320089.74 | BJ13: 320130.64 | BK13: 320165.86 | BL13: 320196.17 | BM13: 320222.27 | BN13: 320244.74 | BO13: 320264.07 | BP13: 320280.72 | BQ13: 320295.05 | BR13: 320307.38 | BS13: 320318 | BT13: 320327.14 | BU13: 320335.01 | BV13: 320341.78
A14: 2017-01 | B14: 101359.18 | C14: 114683.03 | D14: 129313.81 | E14: 145264.67 | F14: 162519.05 | G14: 181026.07 | H14: 200697.19 | I14: 221404.85 | J14: 242983.39 | K14: 265232.77 | L14: 287924.97 | M14: 310812.77 | N14: 333640.31 | O14: 356154.39 | P14: 378115.6 | Q14: 399308.09 | R14: 419547.32 | S14: 438685.25 | T14: 456612.66 | U14: 473259.03 | V14: 488590.07 | W14: 502603.83 | X14: 515325.6 | Y14: 526802.52 | Z14: 537098.16 | AA14: 546287.45 | AB14: 554452.31 | AC14: 561677.86 | AD14: 568049.46 | AE14: 573650.44 | AF14: 578560.45 | AG14: 582854.35 | AH14: 586601.5 | AI14: 589865.5 | AJ14: 592704.08 | AK14: 595169.23 | AL14: 597307.49 | AM14: 599160.25 | AN14: 600764.16 | AO14: 602151.55 | AP14: 603350.83 | AQ14: 604386.89 | AR14: 605281.49 | AS14: 606053.6 | AT14: 606719.75 | AU14: 607294.28 | AV14: 607789.65 | AW14: 608216.67 | AX14: 608584.69 | AY14: 608901.8 | AZ14: 609175.01 | BA14: 609410.36 | BB14: 609613.07 | BC14: 609787.65 | BD14: 609938 | BE14: 610067.46 | BF14: 610178.93 | BG14: 610274.91 | BH14: 610357.55 | BI14: 610428.69 | BJ14: 610489.94 | BK14: 610542.66 | BL14: 610588.05 | BM14: 610627.12 | BN14: 610660.75 | BO14: 610689.7 | BP14: 610714.62 | BQ14: 610736.07 | BR14: 610754.54 | BS14: 610770.43 | BT14: 610784.11 | BU14: 610795.88
A15: 2017-02 | B15: 56917.195 | C15: 64894.373 | D15: 73796.584 | E15: 83676.421 | F15: 94574.314 | G15: 106514.28 | H15: 119499.59 | I15: 133508.66 | J15: 148491.75 | K15: 164368.69 | L15: 181028.39 | M15: 198330.24 | N15: 216107.8 | O15: 234174.5 | P15: 252331.12 | Q15: 270374.45 | R15: 288106.33 | S15: 305342.13 | T15: 321918.14 | U15: 337697.03 | V15: 352571.23 | W15: 366464.15 | X15: 379329.43 | Y15: 391148.55 | Z15: 401927.4 | AA15: 411692.09 | AB15: 420484.69 | AC15: 428358.92 | AD15: 435376.37 | AE15: 441603.08 | AF15: 447106.86 | AG15: 451955.06 | AH15: 456212.93 | AI15: 459942.48 | AJ15: 463201.7 | AK15: 466044.16 | AL15: 468518.77 | AM15: 470669.83 | AN15: 472537.14 | AO15: 474156.26 | AP15: 475558.75 | AQ15: 476772.55 | AR15: 477822.25 | AS15: 478729.45 | AT15: 479513.04 | AU15: 480189.54 | AV15: 480773.34 | AW15: 481276.96 | AX15: 481711.27 | AY15: 482085.72 | AZ15: 482408.47 | BA15: 482686.62 | BB15: 482926.28 | BC15: 483132.74 | BD15: 483310.59 | BE15: 483463.77 | BF15: 483595.69 | BG15: 483709.3 | BH15: 483807.12 | BI15: 483891.35 | BJ15: 483963.87 | BK15: 484026.3 | BL15: 484080.05 | BM15: 484126.33 | BN15: 484166.16 | BO15: 484200.45 | BP15: 484229.97 | BQ15: 484255.38 | BR15: 484277.26 | BS15: 484296.08 | BT15: 484312.29
A16: 2017-03 | B16: 104574.47 | C16: 118595.43 | D16: 134066.82 | E16: 151024.41 | F16: 169474.73 | G16: 189389.14 | H16: 210699.01 | I16: 233292.45 | J16: 257013.36 | K16: 281663.35 | L16: 307006.75 | M16: 332778.61 | N16: 358695.28 | O16: 384466.71 | P16: 409809.27 | Q16: 434458.05 | R16: 458177.41 | S16: 480769.04 | T16: 502076.91 | U16: 521989.18 | V16: 540437.28 | W16: 557392.65 | X16: 572861.84 | Y16: 586880.68 | Z16: 599508.06 | AA16: 610819.87 | AB16: 620903.5 | AC16: 629853.01 | AD16: 637765.1 | AE16: 644736.02 | AF16: 650859.13 | AG16: 656223.24 | AH16: 660911.48 | AI16: 665000.66 | AJ16: 668560.98 | AK16: 671656.05 | AL16: 674343.04 | AM16: 676673.03 | AN16: 678691.4 | AO16: 680438.29 | AP16: 681949.08 | AQ16: 683254.8 | AR16: 684382.66 | AS16: 685356.4 | AT16: 686196.73 | AU16: 686921.66 | AV16: 687546.85 | AW16: 688085.86 | AX16: 688550.46 | AY16: 688950.86 | AZ16: 689295.85 | BA16: 689593.07 | BB16: 689849.09 | BC16: 690069.61 | BD16: 690259.52 | BE16: 690423.06 | BF16: 690563.88 | BG16: 690685.13 | BH16: 690789.53 | BI16: 690879.41 | BJ16: 690956.79 | BK16: 691023.41 | BL16: 691080.76 | BM16: 691130.12 | BN16: 691172.62 | BO16: 691209.2 | BP16: 691240.69 | BQ16: 691267.79 | BR16: 691291.12 | BS16: 691311.21
A17: 2017-04 | B17: 74240.071 | C17: 83881.285 | D17: 94437.102 | E17: 105908.41 | F17: 118274.03 | G17: 131487.78 | H17: 145476.78 | I17: 160141.02 | J17: 175354.88 | K17: 190970.5 | L17: 206822.92 | M17: 222736.84 | N17: 238534.23 | O17: 254042.19 | P17: 269100.43 | Q17: 283567.51 | R17: 297325.48 | S17: 310282.68 | T17: 322374.61 | U17: 333563.11 | V17: 343834.19 | W17: 353194.89 | X17: 361669.65 | Y17: 369296.47 | Z17: 376123.28 | AA17: 382204.55 | AB17: 387598.44 | AC17: 392364.41 | AD17: 396561.38 | AE17: 400246.31 | AF17: 403473.23 | AG17: 406292.64 | AH17: 408751.06 | AI17: 410890.99 | AJ17: 412750.87 | AK17: 414365.22 | AL17: 415764.85 | AM17: 416977.12 | AN17: 418026.2 | AO17: 418933.39 | AP17: 419717.38 | AQ17: 420394.51 | AR17: 420979.08 | AS17: 421483.53 | AT17: 421918.68 | AU17: 422293.93 | AV17: 422617.45 | AW17: 422896.31 | AX17: 423136.62 | AY17: 423343.67 | AZ17: 423522.04 | BA17: 423675.69 | BB17: 423808.03 | BC17: 423922 | BD17: 424020.14 | BE17: 424104.65 | BF17: 424177.41 | BG17: 424240.06 | BH17: 424294 | BI17: 424340.43 | BJ17: 424380.41 | BK17: 424414.82 | BL17: 424444.45 | BM17: 424469.95 | BN17: 424491.9 | BO17: 424510.8 | BP17: 424527.06 | BQ17: 424541.06 | BR17: 424553.11
A18: 2017-05 | B18: 75150.975 | C18: 85082.034 | D18: 96001.313 | E18: 107922.64 | F18: 120838 | G18: 134713.94 | H18: 149488.81 | I18: 165071.36 | J18: 181341.15 | K18: 198150.93 | L18: 215331.14 | M18: 232696.26 | N18: 250052.59 | O18: 267206.85 | P18: 283974.65 | Q18: 300188.19 | R18: 315702.49 | S18: 330399.66 | T18: 344191.16 | U18: 357017.95 | V18: 368848.97 | W18: 379678.37 | X18: 389521.72 | Y18: 398412 | Z18: 406395.41 | AA18: 413527.48 | AB18: 419869.65 | AC18: 425486.27 | AD18: 430442.26 | AE18: 434801.31 | AF18: 438624.5 | AG18: 441969.4 | AH18: 444889.51 | AI18: 447433.94 | AJ18: 449647.37 | AK18: 451570.1 | AL18: 453238.23 | AM18: 454683.89 | AN18: 455935.6 | AO18: 457018.48 | AP18: 457954.66 | AQ18: 458763.51 | AR18: 459461.98 | AS18: 460064.87 | AT18: 460585.05 | AU18: 461033.71 | AV18: 461420.58 | AW18: 461754.08 | AX18: 462041.52 | AY18: 462289.2 | AZ18: 462502.6 | BA18: 462686.43 | BB18: 462844.77 | BC18: 462981.14 | BD18: 463098.58 | BE18: 463199.71 | BF18: 463286.79 | BG18: 463361.77 | BH18: 463426.32 | BI18: 463481.89 | BJ18: 463529.74 | BK18: 463570.92 | BL18: 463606.38 | BM18: 463636.9 | BN18: 463663.18 | BO18: 463685.79 | BP18: 463705.26 | BQ18: 463722.02
A19: 2017-06 | B19: 114403.63 | C19: 129531.83 | D19: 146168.09 | E19: 164334.25 | F19: 184018.96 | G19: 205172.11 | H19: 227700.62 | I19: 251466.27 | J19: 276286.2 | K19: 301936.48 | L19: 328158.92 | M19: 354670.69 | N19: 381176.19 | O19: 407380.11 | P19: 433000.44 | Q19: 457780.24 | R19: 481497.2 | S19: 503970.29 | T19: 525063.2 | U19: 544684.71 | V19: 562786.45 | W19: 579358.59 | X19: 594424.22 | Y19: 608033.11 | Z19: 620255.4 | AA19: 631175.62 | AB19: 640887.39 | AC19: 649488.92 | AD19: 657079.38 | AE19: 663756.05 | AF19: 669612.33 | AG19: 674736.26 | AH19: 679209.68 | AI19: 683107.76 | AJ19: 686498.87 | AK19: 689444.7 | AL19: 692000.53 | AM19: 694215.56 | AN19: 696133.45 | AO19: 697792.7 | AP19: 699227.18 | AQ19: 700466.57 | AR19: 701536.85 | AS19: 702460.67 | AT19: 703257.76 | AU19: 703945.28 | AV19: 704538.1 | AW19: 705049.15 | AX19: 705489.61 | AY19: 705869.16 | AZ19: 706196.16 | BA19: 706477.86 | BB19: 706720.5 | BC19: 706929.48 | BD19: 707109.45 | BE19: 707264.42 | BF19: 707397.86 | BG19: 707512.75 | BH19: 707611.67 | BI19: 707696.83 | BJ19: 707770.15 | BK19: 707833.27 | BL19: 707887.6 | BM19: 707934.37 | BN19: 707974.64 | BO19: 708009.29 | BP19: 708039.13
A20: 2017-07 | B20: 45267.671 | C20: 51420.997 | D20: 58234.277 | E20: 65730.424 | F20: 73920.333 | G20: 82800.049 | H20: 92348.205 | I20: 102524.05 | J20: 113266.39 | K20: 124493.71 | L20: 136105.73 | M20: 147986.3 | N20: 160007.79 | O20: 172036.31 | P20: 183937.71 | Q20: 195583.41 | R20: 206855.87 | S20: 217652.96 | T20: 227891.13 | U20: 237507.04 | V20: 246457.82 | W20: 254720.17 | X20: 262288.44 | Y20: 269172.08 | Z20: 275392.91 | AA20: 280982.15 | AB20: 285977.75 | AC20: 290421.96 | AD20: 294359.24 | AE20: 297834.58 | AF20: 300892.22 | AG20: 303574.67 | AH20: 305922.08 | AI20: 307971.77 | AJ20: 309758.09 | AK20: 311312.25 | AL20: 312662.48 | AM20: 313834.05 | AN20: 314849.48 | AO20: 315728.74 | AP20: 316489.48 | AQ20: 317147.19 | AR20: 317715.48 | AS20: 318206.24 | AT20: 318629.86 | AU20: 318995.38 | AV20: 319310.66 | AW20: 319582.52 | AX20: 319816.88 | AY20: 320018.87 | AZ20: 320192.93 | BA20: 320342.9 | BB20: 320472.09 | BC20: 320583.37 | BD20: 320679.21 | BE20: 320761.75 | BF20: 320832.83 | BG20: 320894.03 | BH20: 320946.72 | BI20: 320992.09 | BJ20: 321031.15 | BK20: 321064.77 | BL20: 321093.72 | BM20: 321118.64 | BN20: 321140.09 | BO20: 321158.56
A21: 2017-08 | B21: 51617.095 | C21: 58577.674 | D21: 66269.339 | E21: 74713.206 | F21: 83916.23 | G21: 93868.159 | H21: 104538.91 | I21: 115876.72 | J21: 127807.32 | K21: 140234.64 | L21: 153042.91 | M21: 166100.48 | N21: 179264.84 | O21: 192388.79 | P21: 205326.91 | Q21: 217941.93 | R21: 230110.34 | S21: 241726.81 | T21: 252707.02 | U21: 262989.07 | V21: 272533.23 | W21: 281320.56 | X21: 289350.61 | Y21: 296638.47 | Z21: 303211.67 | AA21: 309107.09 | AB21: 314368.02 | AC21: 319041.68 | AD21: 323177.05 | AE21: 326823.22 | AF21: 330028.03 | AG21: 332837.2 | AH21: 335293.64 | AI21: 337437.15 | AJ21: 339304.15 | AK21: 340927.71 | AL21: 342337.62 | AM21: 343560.51 | AN21: 344620.08 | AO21: 345537.3 | AP21: 346330.69 | AQ21: 347016.48 | AR21: 347608.93 | AS21: 348120.48 | AT21: 348561.97 | AU21: 348942.87 | AV21: 349271.38 | AW21: 349554.63 | AX21: 349798.79 | AY21: 350009.22 | AZ21: 350190.54 | BA21: 350346.75 | BB21: 350481.31 | BC21: 350597.22 | BD21: 350697.04 | BE21: 350783 | BF21: 350857.02 | BG21: 350920.76 | BH21: 350975.63 | BI21: 351022.88 | BJ21: 351063.55 | BK21: 351098.57 | BL21: 351128.72 | BM21: 351154.67 | BN21: 351177.01
A22: 2017-09 | B22: 58496.175 | C22: 66371.936 | D22: 75071.466 | E22: 84617.607 | F22: 95017.056 | G22: 106256.97 | H22: 118302.04 | I22: 131092.48 | J22: 144543.24 | K22: 158544.82 | L22: 172965.82 | M22: 187657.27 | N22: 202458.43 | O22: 217203.73 | P22: 231730.07 | Q22: 245883.92 | R22: 259527.6 | S22: 272544.1 | T22: 284840.21 | U22: 296347.91 | V22: 307024.09 | W22: 316848.84 | X22: 325822.85 | Y22: 333964.08 | Z22: 341304.25 | AA22: 347885.35 | AB22: 353756.41 | AC22: 358970.7 | AD22: 363583.36 | AE22: 367649.49 | AF22: 371222.78 | AG22: 374354.43 | AH22: 377092.49 | AI22: 379481.43 | AJ22: 381561.98 | AK22: 383371.08 | AL22: 384941.98 | AM22: 386304.42 | AN22: 387484.82 | AO22: 388506.59 | AP22: 389390.37 | AQ22: 390154.27 | AR22: 390814.16 | AS22: 391383.93 | AT22: 391875.67 | AU22: 392299.9 | AV22: 392665.78 | AW22: 392981.24 | AX22: 393253.16 | AY22: 393487.51 | AZ22: 393689.44 | BA22: 393863.41 | BB22: 394013.27 | BC22: 394142.35 | BD22: 394253.51 | BE22: 394349.24 | BF22: 394431.67 | BG22: 394502.65 | BH22: 394563.77 | BI22: 394616.38 | BJ22: 394661.68 | BK22: 394700.67 | BL22: 394734.25 | BM22: 394763.14
A23: 2017-10 | B23: 43243.255 | C23: 49199.191 | D23: 55815.958 | E23: 63122.805 | F23: 71138.312 | G23: 79867.428 | H23: 89298.637 | I23: 99401.55 | J23: 110125.25 | K23: 121397.68 | L23: 133126.4 | M23: 145200.79 | N23: 157495.7 | O23: 169876.41 | P23: 182204.37 | Q23: 194343.4 | R23: 206165.56 | S23: 217556.38 | T23: 228418.8 | U23: 238675.76 | V23: 248271.29 | W23: 257170.22 | X23: 265356.69 | Y23: 272831.96 | Z23: 279611.63 | AA23: 285722.64 | AB23: 291200.44 | AC23: 296086.24 | AD23: 300424.69 | AE23: 304261.94 | AF23: 307644.06 | AG23: 310615.87 | AH23: 313220.09 | AI23: 315496.78 | AJ23: 317483.02 | AK23: 319212.73 | AL23: 320716.67 | AM23: 322022.51 | AN23: 323155.01 | AO23: 324136.15 | AP23: 324985.41 | AQ23: 325719.95 | AR23: 326354.84 | AS23: 326903.28 | AT23: 327376.8 | AU23: 327785.47 | AV23: 328138.03 | AW23: 328442.09 | AX23: 328704.24 | AY23: 328930.22 | AZ23: 329124.97 | BA23: 329292.77 | BB23: 329437.34 | BC23: 329561.88 | BD23: 329669.14 | BE23: 329761.52 | BF23: 329841.07 | BG23: 329909.57 | BH23: 329968.55 | BI23: 330019.34 | BJ23: 330063.06 | BK23: 330100.7 | BL23: 330133.11
A24: 2017-11 | B24: 25542.189 | C24: 29037.821 | D24: 32915.016 | E24: 37188.899 | F24: 41868.052 | G24: 46952.823 | H24: 52433.77 | I24: 58290.384 | J24: 64490.299 | K24: 70989.151 | L24: 77731.226 | M24: 84650.959 | N24: 91675.237 | O24: 98726.368 | P24: 105725.47 | Q24: 112595.96 | R24: 119266.84 | S24: 125675.5 | T24: 131769.74 | U24: 137508.99 | V24: 142864.74 | W24: 147820.14 | X24: 152369.04 | Y24: 156514.61 | Z24: 160267.69 | AA24: 163645.17 | AB24: 166668.29 | AC24: 169361.2 | AD24: 171749.68 | AE24: 173860.07 | AF24: 175718.47 | AG24: 177350.12 | AH24: 178778.96 | AI24: 180027.33 | AJ24: 181115.86 | AK24: 182063.37 | AL24: 182886.87 | AM24: 183601.65 | AN24: 184221.35 | AO24: 184758.1 | AP24: 185222.59 | AQ24: 185624.26 | AR24: 185971.37 | AS24: 186271.18 | AT24: 186530 | AU24: 186753.34 | AV24: 186946.01 | AW24: 187112.15 | AX24: 187255.39 | AY24: 187378.86 | AZ24: 187485.25 | BA24: 187576.93 | BB24: 187655.9 | BC24: 187723.93 | BD24: 187782.52 | BE24: 187832.98 | BF24: 187876.43 | BG24: 187913.85 | BH24: 187946.07 | BI24: 187973.81 | BJ24: 187997.69 | BK24: 188018.24
A25: 2017-12 | B25: 58512.489 | C25: 66515.922 | D25: 75391.716 | E25: 85174.106 | F25: 95882.284 | G25: 107516.55 | H25: 120054.78 | I25: 133449.49 | J25: 147626.13 | K25: 162482.72 | L25: 177891.45 | M25: 193702.1 | N25: 209747.37 | O25: 225849.68 | P25: 241828.9 | Q25: 257510.36 | R25: 272732.33 | S25: 287352.31 | T25: 301251.69 | U25: 314338.51 | V25: 326548.29 | W25: 337843.16 | X25: 348209.62 | Y25: 357655.36 | Z25: 366205.55 | AA25: 373899 | AB25: 380784.43 | AC25: 386917.12 | AD25: 392355.98 | AE25: 397161.19 | AF25: 401392.32 | AG25: 405106.96 | AH25: 408359.67 | AI25: 411201.42 | AJ25: 413679.2 | AK25: 415835.88 | AL25: 417710.24 | AM25: 419337.1 | AN25: 420747.53 | AO25: 421969.12 | AP25: 423026.25 | AQ25: 423940.38 | AR25: 424730.35 | AS25: 425412.64 | AT25: 426001.65 | AU25: 426509.93 | AV25: 426948.38 | AW25: 427326.47 | AX25: 427652.44 | AY25: 427933.41 | AZ25: 428175.53 | BA25: 428384.15 | BB25: 428563.87 | BC25: 428718.68 | BD25: 428852.01 | BE25: 428966.84 | BF25: 429065.72 | BG25: 429150.87 | BH25: 429224.18 | BI25: 429287.3 | BJ25: 429341.64
A26: 2018-01 | B26: 58426.261 | C26: 66435.218 | D26: 75322.024 | E26: 85122.509 | F26: 95857.662 | G26: 107529.74 | H26: 120118.64 | I26: 133578.88 | J26: 147837.68 | K26: 162794.57 | L26: 178322.68 | M26: 194272.09 | N26: 210475.06 | O26: 226752.75 | P26: 242922.99 | Q26: 258808.39 | R26: 274243.94 | S26: 289083.58 | T26: 303205 | U26: 316512.66 | V26: 328938.81 | W26: 340442.71 | X26: 351008.54 | Y26: 360642.22 | Z26: 369367.69 | AA26: 377223.06 | AB26: 384256.78 | AC26: 390524.22 | AD26: 396084.71 | AE26: 400999.04 | AF26: 405327.54 | AG26: 409128.65 | AH26: 412457.85 | AI26: 415367.01 | AJ26: 417904.01 | AK26: 420112.57 | AL26: 422032.28 | AM26: 423698.69 | AN26: 425143.56 | AO26: 426395.08 | AP26: 427478.19 | AQ26: 428414.85 | AR26: 429224.33 | AS26: 429923.51 | AT26: 430527.13 | AU26: 431048.03 | AV26: 431497.38 | AW26: 431884.89 | AX26: 432218.98 | AY26: 432506.95 | AZ26: 432755.11 | BA26: 432968.94 | BB26: 433153.15 | BC26: 433311.83 | BD26: 433448.5 | BE26: 433566.2 | BF26: 433667.55 | BG26: 433754.83 | BH26: 433829.98 | BI26: 433894.68
A27: 2018-02 | B27: 35969.302 | C27: 40922.994 | D27: 46426.204 | E27: 52503.22 | F27: 59169.455 | G27: 66428.977 | H27: 74272.161 | I27: 82673.683 | J27: 91591.143 | K27: 100964.58 | L27: 110717.07 | M27: 120756.6 | N27: 130979.09 | O27: 141272.49 | P27: 151521.64 | Q27: 161613.31 | R27: 171441.18 | S27: 180910.11 | T27: 189939.46 | U27: 198465.24 | V27: 206440.98 | W27: 213837.47 | X27: 220641.61 | Y27: 226854.48 | Z27: 232489.09 | AA27: 237567.88 | AB27: 242120.32 | AC27: 246180.69 | AD27: 249786.14 | AE27: 252975.03 | AF27: 255785.65 | AG27: 258255.27 | AH27: 260419.39 | AI27: 262311.33 | AJ27: 263961.89 | AK27: 265399.26 | AL27: 266649.01 | AM27: 267734.14 | AN27: 268675.22 | AO27: 269490.53 | AP27: 270196.24 | AQ27: 270806.63 | AR27: 271334.2 | AS27: 271789.93 | AT27: 272183.42 | AU27: 272523 | AV27: 272815.97 | AW27: 273068.63 | AX27: 273286.47 | AY27: 273474.25 | AZ27: 273636.08 | BA27: 273775.52 | BB27: 273895.65 | BC27: 273999.13 | BD27: 274088.26 | BE27: 274165.03 | BF27: 274231.13 | BG27: 274288.05 | BH27: 274337.06
A28: 2018-03 | B28: 99139.957 | C28: 111838.49 | D28: 125695.88 | E28: 140701.15 | F28: 156813.63 | G28: 173959.9 | H28: 192032.3 | I28: 210889.52 | J28: 230359.49 | K28: 250244.75 | L28: 270329.89 | M28: 290390.7 | N28: 310204.03 | O28: 329557.65 | P28: 348259 | Q28: 366142.29 | R28: 383073.28 | S28: 398951.76 | T28: 413711.57 | U28: 427318.74 | V28: 439768.18 | W28: 451079.33 | X28: 461291.41 | Y28: 470458.64 | Z28: 478645.8 | AA28: 485924.2 | AB28: 492368.38 | AC28: 498053.39 | AD28: 503052.7 | AE28: 507436.72 | AF28: 511271.72 | AG28: 514619.26 | AH28: 517535.82 | AI28: 520072.73 | AJ28: 522276.26 | AK28: 524187.87 | AL28: 525844.45 | AM28: 527278.69 | AN28: 528519.42 | AO28: 529592.02 | AP28: 530518.71 | AQ28: 531318.92 | AR28: 532009.6 | AS28: 532605.51 | AT28: 533119.49 | AU28: 533562.67 | AV28: 533944.71 | AW28: 534273.97 | AX28: 534557.69 | AY28: 534802.14 | AZ28: 535012.71 | BA28: 535194.09 | BB28: 535350.3 | BC28: 535484.82 | BD28: 535600.66 | BE28: 535700.41 | BF28: 535786.29 | BG28: 535860.23
A29: 2018-04 | B29: 106008.92 | C29: 120271.71 | D29: 136023.59 | E29: 153305.08 | F29: 172127.39 | G29: 192466.25 | H29: 214256.75 | I29: 237389.64 | J29: 261710.11 | K29: 287019.22 | L29: 313078.7 | M29: 339618.79 | N29: 366348.82 | O29: 392969.71 | P29: 419187.23 | Q29: 444724.82 | R29: 469334.74 | S29: 492806.81 | T29: 514973.96 | U29: 535714.62 | V29: 554952.12 | W29: 572651.63 | X29: 588815.33 | Y29: 603476.43 | Z29: 616692.79 | AA29: 628540.68 | AB29: 639108.92 | AC29: 648493.85 | AD29: 656795.07 | AE29: 664112.08 | AF29: 670541.69 | AG29: 676176.24 | AH29: 681102.33 | AI29: 685400.08 | AJ29: 689142.87 | AK29: 692397.19 | AL29: 695222.93 | AM29: 697673.61 | AN29: 699796.79 | AO29: 701634.62 | AP29: 703224.19 | AQ29: 704598.13 | AR29: 705784.99 | AS29: 706809.75 | AT29: 707694.14 | AU29: 708457.13 | AV29: 709115.15 | AW29: 709682.49 | AX29: 710171.54 | AY29: 710593.01 | AZ29: 710956.17 | BA29: 711269.04 | BB29: 711538.55 | BC29: 711770.69 | BD29: 711970.61 | BE29: 712142.77 | BF29: 712291.02
A30: 2018-05 | B30: 50160.973 | C30: 56571.369 | D30: 63563.011 | E30: 71129.377 | F30: 79248.93 | G30: 87883.622 | H30: 96978.22 | I30: 106460.67 | J30: 116243.66 | K30: 126227.36 | L30: 136303.27 | M30: 146358.82 | N30: 156282.32 | O30: 165967.91 | P30: 175319.89 | Q30: 184256.17 | R30: 192710.66 | S30: 200634.34 | T30: 207995.22 | U30: 214777.39 | V30: 220979.27 | W30: 226611.39 | X30: 231694.05 | Y30: 236254.91 | Z30: 240326.73 | AA30: 243945.47 | AB30: 247148.55 | AC30: 249973.6 | AD30: 252457.38 | AE30: 254635.04 | AF30: 256539.69 | AG30: 258201.99 | AH30: 259650.1 | AI30: 260909.57 | AJ30: 262003.43 | AK30: 262952.29 | AL30: 263774.51 | AM30: 264486.33 | AN30: 265102.08 | AO30: 265634.36 | AP30: 266094.21 | AQ30: 266491.29 | AR30: 266834 | AS30: 267129.69 | AT30: 267384.71 | AU30: 267604.61 | AV30: 267794.16 | AW30: 267957.52 | AX30: 268098.29 | AY30: 268219.57 | AZ30: 268324.04 | BA30: 268414.03 | BB30: 268491.53 | BC30: 268558.27 | BD30: 268615.74 | BE30: 268665.23
A31: 2018-06 | B31: 76798.853 | C31: 87234.234 | D31: 98787.7 | E31: 111497.75 | F31: 125382.47 | G31: 140434.71 | H31: 156617.8 | I31: 173862.19 | J31: 192063.71 | K31: 211083.85 | L31: 230752.3 | M31: 250872.08 | N31: 271226.83 | O31: 291589.82 | P31: 311733.97 | Q31: 331441.83 | R31: 350514.78 | S31: 368780.38 | T31: 386097.7 | U31: 402360.06 | V31: 417495.47 | W31: 431464.96 | X31: 444259.39 | Y31: 455895.2 | Z31: 466409.57 | AA31: 475855.59 | AB31: 484297.68 | AC31: 491807.43 | AD31: 498460.16 | AE31: 504332.03 | AF31: 509497.91 | AG31: 514029.73 | AH31: 517995.35 | AI31: 521457.92 | AJ31: 524475.46 | AK31: 527100.79 | AL31: 529381.57 | AM31: 531360.52 | AN31: 533075.7 | AO31: 534560.86 | AP31: 535845.8 | AQ31: 536956.71 | AR31: 537916.57 | AS31: 538745.49 | AT31: 539460.99 | AU31: 540078.35 | AV31: 540610.85 | AW31: 541070.02 | AX31: 541465.86 | AY31: 541807.02 | AZ31: 542101.01 | BA31: 542354.3 | BB31: 542572.5 | BC31: 542760.44 | BD31: 542922.32
A32: 2018-07 | B32: 40146.504 | C32: 45596.235 | D32: 51628.378 | E32: 58262.572 | F32: 65507.733 | G32: 73359.565 | H32: 81798.325 | I32: 90787.132 | J32: 100271.08 | K32: 110177.42 | L32: 120416.98 | M32: 130886.82 | N32: 141474.13 | O32: 152060.88 | P32: 162529.1 | Q32: 172766.02 | R32: 182668.84 | S32: 192148.5 | T32: 201132.44 | U32: 209565.9 | V32: 217412.18 | W32: 224651.67 | X32: 231280.23 | Y32: 237306.87 | Z32: 242751.32 | AA32: 247641.49 | AB32: 252011.04 | AC32: 255897.33 | AD32: 259339.56 | AE32: 262377.34 | AF32: 265049.56 | AG32: 267393.52 | AH32: 269444.44 | AI32: 271235.05 | AJ32: 272795.4 | AK32: 274152.86 | AL32: 275332.1 | AM32: 276355.24 | AN32: 277241.96 | AO32: 278009.75 | AP32: 278674 | AQ32: 279248.27 | AR32: 279744.45 | AS32: 280172.93 | AT32: 280542.78 | AU32: 280861.9 | AV32: 281137.14 | AW32: 281374.48 | AX32: 281579.08 | AY32: 281755.42 | AZ32: 281907.38 | BA32: 282038.3 | BB32: 282151.08 | BC32: 282248.22
A33: 2018-08 | B33: 32283.461 | C33: 36771.252 | D33: 41768.846 | E33: 47302.217 | F33: 53389.904 | G33: 60040.678 | H33: 67251.242 | I33: 75004.153 | J33: 83266.229 | K33: 91987.694 | L33: 101102.29 | M33: 110528.51 | N33: 120172.04 | O33: 129929.23 | P33: 139691.4 | Q33: 149349.68 | R33: 158799.76 | S33: 167946.32 | T33: 176706.57 | U33: 185012.79 | V33: 192813.69 | W33: 200074.59 | X33: 206776.68 | Y33: 212915.45 | Z33: 218498.66 | AA33: 223544.06 | AB33: 228077.05 | AC33: 232128.46 | AD33: 235732.58 | AE33: 238925.51 | AF33: 241743.77 | AG33: 244223.25 | AH33: 246398.46 | AI33: 248301.94 | AJ33: 249963.99 | AK33: 251412.45 | AL33: 252672.66 | AM33: 253767.49 | AN33: 254717.45 | AO33: 255540.8 | AP33: 256253.74 | AQ33: 256870.56 | AR33: 257403.85 | AS33: 257864.64 | AT33: 258262.56 | AU33: 258606.04 | AV33: 258902.41 | AW33: 259158.04 | AX33: 259378.46 | AY33: 259568.49 | AZ33: 259732.27 | BA33: 259873.4 | BB33: 259994.99
A34: 2018-09 | B34: 30230.176 | C34: 34445.072 | D34: 39142.382 | E34: 44347.725 | F34: 50079.929 | G34: 56348.823 | H34: 63153.026 | I34: 70477.918 | J34: 78294.047 | K34: 86556.187 | L34: 95203.311 | M34: 104159.61 | N34: 113336.66 | O34: 122636.59 | P34: 131956.13 | Q34: 141191.14 | R34: 150241.24 | S34: 159014.01 | T34: 167428.6 | U34: 175418.27 | V34: 182931.79 | W34: 189933.88 | X34: 196404.49 | Y34: 202337.5 | Z34: 207738.78 | AA34: 212624.06 | AB34: 217016.64 | AC34: 220945.34 | AD34: 224442.5 | AE34: 227542.42 | AF34: 230279.93 | AG34: 232689.43 | AH34: 234804.05 | AI34: 236655.14 | AJ34: 238271.92 | AK34: 239681.28 | AL34: 240907.76 | AM34: 241973.49 | AN34: 242898.35 | AO34: 243700.07 | AP34: 244394.36 | AQ34: 244995.12 | AR34: 245514.57 | AS34: 245963.43 | AT34: 246351.08 | AU34: 246685.72 | AV34: 246974.47 | AW34: 247223.55 | AX34: 247438.33 | AY34: 247623.5 | AZ34: 247783.09 | BA34: 247920.62
A35: 2018-10 | B35: 37706.867 | C35: 42850.828 | D35: 48551.643 | E35: 54830.095 | F35: 61697.133 | G35: 69151.445 | H35: 77177.231 | I35: 85742.44 | J35: 94797.735 | K35: 104276.43 | L35: 114095.62 | M35: 124158.49 | N35: 134357.81 | O35: 144580.38 | P35: 154711.96 | Q35: 164642.32 | R35: 174269.95 | S35: 183505.95 | T35: 192276.85 | U35: 200526.22 | V35: 208215.09 | W35: 215321.22 | X35: 221837.69 | Y35: 227770.77 | Z35: 233137.53 | AA35: 237963.45 | AB35: 242280.04 | AC35: 246122.77 | AD35: 249529.19 | AE35: 252537.54 | AF35: 255185.55 | AG35: 257509.58 | AH35: 259544.06 | AI35: 261321.07 | AJ35: 262870.16 | AK35: 264218.25 | AL35: 265389.69 | AM35: 266406.3 | AN35: 267287.57 | AO35: 268050.76 | AP35: 268711.15 | AQ35: 269282.16 | AR35: 269775.58 | AS35: 270201.72 | AT35: 270569.58 | AU35: 270887.01 | AV35: 271160.81 | AW35: 271396.93 | AX35: 271600.48 | AY35: 271775.92 | AZ35: 271927.11
A36: 2018-11 | B36: 23067.35 | C36: 26160.167 | D36: 29572.934 | E36: 33313.547 | F36: 37383.445 | G36: 41776.319 | H36: 46477.03 | I36: 51460.899 | J36: 56693.496 | K36: 62131.062 | L36: 67721.61 | M36: 73406.697 | N36: 79123.755 | O36: 84808.796 | P36: 90399.254 | Q36: 95836.69 | R36: 101069.12 | S36: 106052.8 | T36: 110753.29 | U36: 115145.94 | V36: 119215.6 | W36: 122955.98 | X36: 126368.51 | Y36: 129461.1 | Z36: 132246.73 | AA36: 134742.16 | AB36: 136966.64 | AC36: 138940.94 | AD36: 140686.38 | AE36: 142224.2 | AF36: 143574.99 | AG36: 144758.34 | AH36: 145792.59 | AI36: 146694.68 | AJ36: 147480.11 | AK36: 148162.9 | AL36: 148755.66 | AM36: 149269.67 | AN36: 149714.94 | AO36: 150100.31 | AP36: 150433.6 | AQ36: 150721.65 | AR36: 150970.46 | AS36: 151185.28 | AT36: 151370.66 | AU36: 151530.59 | AV36: 151668.5 | AW36: 151787.41 | AX36: 151889.91 | AY36: 151978.24
A37: 2018-12 | B37: 48530.001 | C37: 55193.852 | D37: 62591.356 | E37: 70753.373 | F37: 79698.559 | G37: 89430.105 | H37: 99932.651 | I37: 111169.72 | J37: 123082.04 | K37: 135587.05 | L37: 148579.92 | M37: 161936.23 | N37: 175516.23 | O37: 189170.38 | P37: 202745.86 | Q37: 216093.34 | R37: 229073.43 | S37: 241562.25 | T37: 253455.61 | U37: 264671.62 | V37: 275151.7 | W37: 284860.03 | X37: 293781.84 | Y37: 301920.83 | Z37: 309296.07 | AA37: 315938.72 | AB37: 321888.88 | AC37: 327192.66 | AD37: 331899.63 | AE37: 336060.77 | AF37: 339726.76 | AG37: 342946.76 | AH37: 345767.51 | AI37: 348232.78 | AJ37: 350382.99 | AK37: 352255.06 | AL37: 353882.46 | AM37: 355295.27 | AN37: 356520.34 | AO37: 357581.56 | AP37: 358500.04 | AQ37: 359294.36 | AR37: 359980.86 | AS37: 360573.85 | AT37: 361085.8 | AU37: 361527.6 | AV37: 361908.74 | AW37: 362237.43 | AX37: 362520.81
A38: 2019-01 | B38: 54986.965 | C38: 62354.255 | D38: 70482.253 | E38: 79389.335 | F38: 89078.452 | G38: 99534.068 | H38: 110719.62 | I38: 122575.84 | J38: 135020.32 | K38: 147948.52 | L38: 161236.48 | M38: 174745.02 | N38: 188325.33 | O38: 201825.41 | P38: 215096.83 | Q38: 228001.13 | R38: 240415.32 | S38: 252236.06 | T38: 263382.2 | U38: 273795.78 | V38: 283441.45 | W38: 292304.8 | X38: 300389.71 | Y38: 307715.33 | Z38: 314312.79 | AA38: 320222.08 | AB38: 325489.11 | AC38: 330163.21 | AD38: 334295.09 | AE38: 337935.15 | AF38: 341132.26 | AG38: 343932.87 | AH38: 346380.47 | AI38: 348515.2 | AJ38: 350373.76 | AK38: 351989.39 | AL38: 353391.95 | AM38: 354608.13 | AN38: 355661.63 | AO38: 356573.41 | AP38: 357361.93 | AQ38: 358043.42 | AR38: 358632.07 | AS38: 359140.28 | AT38: 359578.85 | AU38: 359957.19 | AV38: 360283.47 | AW38: 360564.77
A39: 2019-02 | B39: 63833.996 | C39: 72499.891 | D39: 82092.098 | E39: 92641.905 | F39: 104163.56 | G39: 116650.29 | H39: 130070.8 | I39: 144366.49 | J39: 159450.12 | K39: 175206.08 | L39: 191492.57 | M39: 208145.94 | N39: 224986.75 | O39: 241827.3 | P39: 258479.89 | Q39: 274765.12 | R39: 290519.39 | S39: 305600.98 | T39: 319894.34 | U39: 333312.31 | V39: 345796.39 | W39: 357315.34 | X39: 367862.45 | Y39: 377452.02 | Z39: 386115.39 | AA39: 393896.9 | AB39: 400850.09 | AC39: 407034.36 | AD39: 412512.07 | AE39: 417346.23 | AF39: 421598.67 | AG39: 425328.79 | AH39: 428592.6 | AI39: 431442.16 | AJ39: 433925.31 | AK39: 436085.59 | AL39: 437962.25 | AM39: 439590.49 | AN39: 441001.66 | AO39: 442223.53 | AP39: 443280.65 | AQ39: 444194.57 | AR39: 444984.21 | AS39: 445666.12 | AT39: 446254.71 | AU39: 446762.57 | AV39: 447200.61
A40: 2019-03 | B40: 88955.918 | C40: 101306.28 | D40: 115055.14 | E40: 130272.49 | F40: 147007.59 | G40: 165282.65 | H40: 185086.5 | I40: 206369.01 | J40: 229036.79 | K40: 252951.04 | L40: 277928.01 | M40: 303742.57 | N40: 330135.03 | O40: 356820.83 | P40: 383502.48 | Q40: 409882.66 | R40: 435677.35 | S40: 460627.71 | T40: 484509.68 | U40: 507140.71 | V40: 528383.26 | W40: 548145.21 | X40: 566377.56 | Y40: 583070.14 | Z40: 598245.99 | AA40: 611955.05 | AB40: 624267.79 | AC40: 635269.21 | AD40: 645053.5 | AE40: 653719.5 | AF40: 661367.04 | AG40: 668094.07 | AH40: 673994.63 | AI40: 679157.39 | AJ40: 683664.77 | AK40: 687592.5 | AL40: 691009.44 | AM40: 693977.74 | AN40: 696553.07 | AO40: 698785.04 | AP40: 700717.6 | AQ40: 702389.55 | AR40: 703835.01 | AS40: 705083.9 | AT40: 706162.38 | AU40: 707093.29
...

Sheet Incremental
A1: accident_period | B1: 0 | C1: 1 | D1: 2 | E1: 3 | F1: 4 | G1: 5 | H1: 6 | I1: 7 | J1: 8 | K1: 9 | L1: 10 | M1: 11 | N1: 12 | O1: 13 | P1: 14 | Q1: 15 | R1: 16 | S1: 17 | T1: 18 | U1: 19 | V1: 20 | W1: 21 | X1: 22 | Y1: 23 | Z1: 24 | AA1: 25 | AB1: 26 | AC1: 27 | AD1: 28 | AE1: 29 | AF1: 30 | AG1: 31 | AH1: 32 | AI1: 33 | AJ1: 34 | AK1: 35 | AL1: 36 | AM1: 37 | AN1: 38 | AO1: 39 | AP1: 40 | AQ1: 41 | AR1: 42 | AS1: 43 | AT1: 44 | AU1: 45 | AV1: 46 | AW1: 47 | AX1: 48 | AY1: 49 | AZ1: 50 | BA1: 51 | BB1: 52 | BC1: 53 | BD1: 54 | BE1: 55 | BF1: 56 | BG1: 57 | BH1: 58 | BI1: 59 | BJ1: 60 | BK1: 61 | BL1: 62 | BM1: 63 | BN1: 64 | BO1: 65 | BP1: 66 | BQ1: 67 | BR1: 68 | BS1: 69 | BT1: 70 | BU1: 71 | BV1: 72 | BW1: 73 | BX1: 74 | BY1: 75 | BZ1: 76 | CA1: 77 | CB1: 78 | CC1: 79 | CD1: 80 | CE1: 81 | CF1: 82 | CG1: 83
A2: 2016-01 | B2: 37434.057 | C2: 5098.0495 | D2: 5647.4998 | E2: 6216.7753 | F2: 6796.0306 | G2: 7373.0381 | H2: 7933.4058 | I2: 8461.0485 | J2: 8938.924 | K2: 9350.0136 | L2: 9678.4744 | M2: 9910.8492 | N2: 10037.19 | O2: 10051.938 | P2: 9954.4388 | Q2: 9748.9997 | R2: 9444.4927 | S2: 9053.5585 | T2: 8591.5325 | U2: 8075.2416 | V2: 7521.8252 | W2: 6947.7005 | X2: 6367.7587 | Y2: 5794.8241 | Z2: 5239.3735 | AA2: 4709.4793 | AB2: 4210.9262 | AC2: 3747.4454 | AD2: 3321.0144 | AE2: 2932.1822 | AF2: 2580.3861 | AG2: 2264.2422 | AH2: 1981.797 | AI2: 1730.736 | AJ2: 1508.5508 | AK2: 1312.6671 | AL2: 1140.5388 | AM2: 989.71502 | AN2: 857.88336 | AO2: 742.89682 | AP2: 642.78674 | AQ2: 555.7663 | AR2: 480.22723 | AS2: 414.73187 | AT2: 358.00245 | AU2: 308.90873 | AV2: 266.45499 | AW2: 229.76703 | AX2: 198.07954 | AY2: 170.72418 | AZ2: 147.11849 | BA2: 126.75578 | BB2: 109.19596 | BC2: 94.057218 | BD2: 81.008739 | BE2: 69.764123 | BF2: 60.075641 | BG2: 51.729159 | BH2: 44.539693 | BI2: 38.347523 | BJ2: 33.014804 | BK2: 28.422616 | BL2: 24.468397 | BM2: 21.06372 | BN2: 18.132361 | BO2: 15.60863 | BP2: 13.435927 | BQ2: 11.565487 | BR2: 9.9553057 | BS2: 8.5692027 | BT2: 7.3760194 | BU2: 6.3489234 | BV2: 5.4648096 | BW2: 4.7037835 | BX2: 4.048716 | BY2: 3.48486 | BZ2: 2.9995193 | CA2: 2.5817638 | CB2: 2.2221845 | CC2: 1.9126814 | CD2: 1.646282 | CE2: 1.4169842 | CF2: 1.2196216 | CG2: 1.0497469
A3: 2016-02 | B3: 88815.648 | C3: 12287.834 | D3: 13666.953 | E3: 15111.602 | F3: 16600.542 | G3: 18106.29 | H3: 19595.285 | I3: 21028.651 | J3: 22363.628 | K3: 23555.694 | L3: 24561.27 | M3: 25340.793 | N3: 25861.832 | O3: 26101.856 | P3: 26050.253 | Q3: 25709.316 | R3: 25094.03 | S3: 24230.694 | T3: 23154.592 | U3: 21907.066 | V3: 20532.365 | W3: 19074.672 | X3: 17575.586 | Y3: 16072.235 | Z3: 14596.093 | AA3: 13172.436 | AB3: 11820.349 | AC3: 10553.138 | AD3: 9379.0042 | AE3: 8301.8542 | AF3: 7322.1415 | AG3: 6437.6747 | AH3: 5644.3424 | AI3: 4936.7325 | AJ3: 4308.6406 | AK3: 3753.4706 | AL3: 3264.539 | AM3: 2835.2962 | AN3: 2459.4793 | AO3: 2131.2115 | AP3: 1845.0584 | AQ3: 1596.0538 | AR3: 1379.7026 | AS3: 1191.9679 | AT3: 1029.2479 | AU3: 888.34621 | AV3: 766.43943 | AW3: 661.04283 | AX3: 569.97697 | AY3: 491.33539 | AZ3: 423.45434 | BA3: 364.8847 | BB3: 314.36649 | BC3: 270.80572 | BD3: 233.25373 | BE3: 200.88874 | BF3: 172.99951 | BG3: 148.97099 | BH3: 128.27161 | BI3: 110.44227 | BJ3: 95.086617 | BK3: 81.862614 | BL3: 70.475222 | BM3: 60.670011 | BN3: 52.227629 | BO3: 44.95901 | BP3: 38.701227 | BQ3: 33.313899 | BR3: 28.67609 | BS3: 24.68363 | BT3: 21.246798 | BU3: 18.288327 | BV3: 15.741677 | BW3: 13.549557 | BX3: 11.662634 | BY3: 10.038435 | BZ3: 8.6403924 | CA3: 7.4370262 | CB3: 6.401235 | CC3: 5.5096882 | CD3: 4.7423023 | CE3: 4.0817891 | CF3: 3.5132668
A4: 2016-03 | B4: 154494.7 | C4: 20944.261 | D4: 23174.838 | E4: 25478.471 | F4: 27813.662 | G4: 30129.412 | H4: 32366.287 | I4: 34458.513 | J4: 36337.144 | K4: 37934.169 | L4: 39187.237 | M4: 40044.509 | N4: 40469.048 | O4: 40442.118 | P4: 39964.915 | Q4: 39058.459 | R4: 37761.654 | S4: 36127.826 | T4: 34220.257 | U4: 32107.305 | V4: 29857.74 | W4: 27536.728 | X4: 25202.793 | Y4: 22905.844 | Z4: 20686.225 | AA4: 18574.642 | AB4: 16592.738 | AC4: 14754.098 | AD4: 13065.491 | AE4: 11528.183 | AF4: 10139.193 | AG4: 8892.4382 | AH4: 7779.7156 | AI4: 6791.5093 | AJ4: 5917.6316 | AK4: 5147.7109 | AL4: 4471.5487 | AM4: 3879.369 | AN4: 3361.9798 | AO4: 2910.868 | AP4: 2518.2443 | AQ4: 2177.0512 | AR4: 1880.9449 | AS4: 1624.2617 | AT4: 1401.9723 | AU4: 1209.632 | AV4: 1043.3278 | AW4: 899.62612 | AX4: 775.52269 | AY4: 668.39491 | AZ4: 575.95811 | BA4: 496.22539 | BB4: 427.47136 | BC4: 368.19963 | BD4: 317.11379 | BE4: 273.09173 | BF4: 235.16296 | BG4: 202.48872 | BH4: 174.3445 | BI4: 150.1048 | BJ4: 129.22982 | BK4: 111.25391 | BL4: 95.775479 | BM4: 82.44832 | BN4: 70.974005 | BO4: 61.09536 | BP4: 52.590797 | BQ4: 45.269418 | BR4: 38.966787 | BS4: 33.541275 | BT4: 28.87091 | BU4: 24.850658 | BV4: 21.390075 | BW4: 18.411286 | BX4: 15.847243 | BY4: 13.640221 | BZ4: 11.740522 | CA4: 10.105366 | CB4: 8.69792 | CC4: 7.4864813 | CD4: 6.4437572 | CE4: 5.5462547
A5: 2016-04 | B5: 103617.09 | C5: 13809.99 | D5: 15216.074 | E5: 16650.684 | F5: 18084.304 | G5: 19481.944 | H5: 20804.208 | I5: 22009.037 | J5: 23054.056 | K5: 23899.391 | L5: 24510.666 | M5: 24861.846 | N5: 24937.526 | O5: 24734.344 | P5: 24261.293 | Q5: 23538.888 | R5: 22597.314 | S5: 21473.84 | T5: 20209.855 | U5: 18847.917 | V5: 17429.12 | W5: 15991.015 | X5: 14566.177 | Y5: 13181.418 | Z5: 11857.583 | AA5: 10609.778 | AB5: 9447.9271 | AC5: 8377.4941 | AD5: 7400.2876 | AE5: 6515.253 | AF5: 5719.2036 | AG5: 5007.4592 | AH5: 4374.3788 | AI5: 3813.7885 | AJ5: 3319.3117 | AK5: 2884.6138 | AL5: 2503.5764 | AM5: 2170.4127 | AN5: 1879.7388 | AO5: 1626.6101 | AP5: 1406.5329 | AQ5: 1215.4582 | AR5: 1049.7633 | AS5: 906.22594 | AT5: 781.99424 | AU5: 674.5544 | AV5: 581.6984 | AW5: 501.49253 | AX5: 432.24754 | AY5: 372.49089 | AZ5: 320.94129 | BA5: 276.48557 | BB5: 238.15792 | BC5: 205.12131 | BD5: 176.65105 | BE5: 152.12022 | BF5: 130.98688 | BG5: 112.7828 | BH5: 97.103712 | BI5: 83.600657 | BJ5: 71.972588 | BK5: 61.959857 | BL5: 53.338589 | BM5: 45.9158 | BN5: 39.525171 | BO5: 34.023391 | BP5: 29.286991 | BQ5: 25.209612 | BR5: 21.699644 | BS5: 18.67819 | BT5: 16.077307 | BU5: 13.838488 | BV5: 11.911358 | BW5: 10.252543 | BX5: 8.8246981 | BY5: 7.5956755 | BZ5: 6.5377973 | CA5: 5.6272372 | CB5: 4.8434841 | CC5: 4.1688819 | CD5: 3.5882317
A6: 2016-05 | B6: 45657.879 | C6: 6135.1707 | D6: 6773.5573 | E6: 7428.7268 | F6: 8087.99 | G6: 8736.0508 | H6: 9355.4059 | I6: 9927.0458 | J6: 10431.451 | K6: 10849.824 | L6: 11165.46 | M6: 11365.085 | N6: 11440.007 | O6: 11386.905 | P6: 11208.136 | Q6: 10911.517 | R6: 10509.611 | S6: 10018.63 | T6: 9457.11 | U6: 8844.5408 | V6: 8200.0971 | W6: 7541.5978 | X6: 6884.7533 | Y6: 6242.7147 | Z6: 5625.9 | AA6: 5042.0446 | AB6: 4496.4147 | AC6: 3992.1214 | AD6: 3530.482 | AE6: 3111.3881 | AF6: 2733.6524 | AG6: 2395.3153 | AH6: 2093.9051 | AI6: 1826.6488 | AJ6: 1590.6373 | AK6: 1382.9494 | AL6: 1200.7407 | AM6: 1041.3052 | AN6: 902.11289 | AO6: 780.83163 | AP6: 675.33533 | AQ6: 583.70348 | AR6: 504.21419 | AS6: 435.33328 | AT6: 375.70085 | AU6: 324.11681 | AV6: 279.52591 | AW6: 241.00322 | AX6: 207.74011 | AY6: 179.03126 | AZ6: 154.26262 | BA6: 132.90044 | BB6: 114.48147 | BC6: 98.604093 | BD6: 84.920478 | BE6: 73.129657 | BF6: 62.971395 | BG6: 54.220823 | BH6: 46.683743 | BI6: 40.192519 | BJ6: 34.602507 | BK6: 29.788942 | BL6: 25.64424 | BM6: 22.075655 | BN6: 19.003251 | BO6: 16.358145 | BP6: 14.080991 | BQ6: 12.120662 | BR6: 10.433121 | BS6: 8.9804422 | BT6: 7.7299615 | BU6: 6.6535531 | BV6: 5.7269985 | BW6: 4.9294455 | BX6: 4.2429405 | BY6: 3.6520272 | BZ6: 3.143399 | CA6: 2.7056004 | CB6: 2.3287703 | CC6: 2.0044196
A7: 2016-06 | B7: 52017.537 | C7: 7166.699 | D7: 7962.5139 | E7: 8793.7344 | F7: 9647.5548 | G7: 10507.596 | H7: 11354.064 | I7: 12164.25 | J7: 12913.429 | K7: 13576.137 | L7: 14127.775 | M7: 14546.379 | N7: 14814.381 | O7: 14920.129 | P7: 14858.936 | Q7: 14633.521 | R7: 14253.75 | S7: 13735.74 | T7: 13100.443 | U7: 12371.931 | V7: 11575.603 | W7: 10736.523 | X7: 9878.0435 | Y7: 9020.8041 | Z7: 8182.1274 | AA7: 7375.7744 | AB7: 6611.9986 | AC7: 5897.8158 | AD7: 5237.4091 | AE7: 4632.5985 | AF7: 4083.3222 | AG7: 3588.0898 | AH7: 3144.3859 | AI7: 2749.0121 | AJ7: 2398.3653 | AK7: 2088.6557 | AL7: 1816.0708 | AM7: 1576.894 | AN7: 1367.5856 | AO7: 1184.8341 | AP7: 1025.5846 | AQ7: 887.0511 | AR7: 766.71595 | AS7: 662.32105 | AT7: 571.85391 | AU7: 493.53029 | AV7: 425.77528 | AW7: 367.20384 | AX7: 316.6018 | AY7: 272.90755 | AZ7: 235.19499 | BA7: 202.65781 | BB7: 174.5951 | BC7: 150.39846 | BD7: 129.54043 | BE7: 111.56417 | BF7: 96.074355 | BG7: 82.729169 | BH7: 71.233235 | BI7: 61.331456 | BJ7: 52.803625 | BK7: 45.45973 | BL7: 39.135874 | BM7: 33.690725 | BN7: 29.002445 | BO7: 24.966022 | BP7: 21.490963 | BQ7: 18.499302 | BR7: 15.923874 | BS7: 13.706826 | BT7: 11.79833 | BU7: 10.155477 | BV7: 8.7413153 | BW7: 7.5240272 | BX7: 6.476218 | BY7: 5.5743013 | BZ7: 4.7979706 | CA7: 4.1297442 | CB7: 3.5545724
A8: 2016-07 | B8: 53298.34 | C8: 7236.3752 | D8: 8010.0977 | E8: 8810.013 | F8: 9621.9 | G8: 10428.222 | H8: 11208.476 | I8: 11939.896 | J8: 12598.536 | K8: 13160.678 | L8: 13604.466 | M8: 13911.598 | N8: 14068.867 | O8: 14069.34 | P8: 13912.996 | Q8: 13606.727 | R8: 13163.707 | S8: 12602.211 | T8: 11944.079 | U8: 11213.023 | V8: 10432.992 | W8: 9626.7628 | X8: 8814.8537 | Y8: 8014.821 | Z8: 7240.9061 | AA8: 6503.9919 | AB8: 5811.7918 | AC8: 5169.1928 | AD8: 4578.6837 | AE8: 4040.8101 | AF8: 3554.6153 | AG8: 3118.0408 | AH8: 2728.271 | AI8: 2382.0178 | AJ8: 2075.7476 | AK8: 1805.8533 | AL8: 1568.7819 | AM8: 1361.1224 | AN8: 1179.6644 | AO8: 1021.4322 | AP8: 883.70103 | AQ8: 764.00084 | AR8: 660.1104 | AS8: 570.04575 | AT8: 492.0447 | AU8: 424.54941 | AV8: 366.18811 | AW8: 315.7569 | AX8: 272.20219 | AY8: 234.60415 | AZ8: 202.16136 | BA8: 174.17679 | BB8: 150.04509 | BC8: 129.24124 | BD8: 111.31034 | BE8: 95.85861 | BF8: 82.545503 | BG8: 71.076656 | BH8: 61.197802 | BI8: 52.689414 | BJ8: 45.362041 | BK8: 39.052247 | BL8: 33.619084 | BM8: 28.941033 | BN8: 24.913349 | BO8: 21.445764 | BP8: 18.4605 | BQ8: 15.890553 | BR8: 13.678202 | BS8: 11.773735 | BT8: 10.134338 | BU8: 8.7231433 | BV8: 7.5084033 | BW8: 6.4627828 | BX8: 5.5627467 | BY8: 4.7880323 | BZ8: 4.1211953 | CA8: 3.547218
A9: 2016-08 | B9: 26669.238 | C9: 3649.9057 | D9: 4048.3149 | E9: 4462.5218 | F9: 4885.69 | G9: 5309.2265 | H9: 5722.9063 | I9: 6115.1763 | J9: 6473.6544 | K9: 6785.8129 | L9: 7039.8008 | M9: 7225.3299 | N9: 7334.5191 | O9: 7362.586 | P9: 7308.2839 | Q9: 7174.0183 | R9: 6965.6233 | S9: 6691.8341 | T9: 6363.5344 | U9: 5992.8864 | V9: 5592.4556 | W9: 5174.425 | X9: 4749.9683 | Y9: 4328.8127 | Z9: 3918.9956 | AA9: 3526.7913 | AB9: 3156.7728 | AC9: 2811.9692 | AD9: 2494.0774 | AE9: 2203.6986 | AF9: 1940.5729 | AG9: 1703.797 | AH9: 1492.0144 | AI9: 1303.5752 | AJ9: 1136.6645 | AK9: 989.40129 | AL9: 859.91304 | AM9: 746.38781 | AN9: 647.10979 | AO9: 560.48093 | AP9: 485.03243 | AQ9: 419.42851 | AR9: 362.46494 | AS9: 313.06379 | AT9: 270.26594 | AU9: 233.22222 | AV9: 201.18394 | AW9: 173.49333 | AX9: 149.57424 | AY9: 128.92325 | AZ9: 111.10149 | BA9: 95.727024 | BB9: 82.468011 | BC9: 71.036505 | BD9: 61.182944 | BE9: 52.691241 | BF9: 45.374453 | BG9: 39.070969 | BH9: 33.641159 | BI9: 28.964453 | BJ9: 24.936783 | BK9: 21.468362 | BL9: 18.481751 | BM9: 15.910177 | BN9: 13.696081 | BO9: 11.789857 | BP9: 10.148757 | BQ9: 8.7359563 | BR9: 7.5197297 | BS9: 6.4727524 | BT9: 5.5714913 | BU9: 4.7956801 | BV9: 4.1278676 | BW9: 3.5530275 | BX9: 3.0582221 | BY9: 2.6323124 | BZ9: 2.2657087
A10: 2016-09 | B10: 24635.962 | C10: 3396.944 | D10: 3774.9291 | E10: 4169.9508 | F10: 4575.9767 | G10: 4985.2741 | H10: 5388.4792 | I10: 5774.8304 | J10: 6132.5871 | K10: 6449.6334 | L10: 6714.2334 | M10: 6915.8754 | N10: 7046.1113 | O10: 7099.2835 | P10: 7073.037 | Q10: 6968.5376 | R10: 6790.3634 | S10: 6546.086 | T10: 6245.6061 | U10: 5900.3398 | V10: 5522.3646 | W10: 5123.6252 | X10: 4715.2726 | Y10: 4307.1814 | Z10: 3907.6544 | AA10: 3523.3013 | AB10: 3159.0599 | AC10: 2818.3214 | AD10: 2503.1211 | AE10: 2214.3617 | AF10: 1952.0424 | AG10: 1715.4751 | AH10: 1503.4774 | AI10: 1314.5366 | AJ10: 1146.9432 | AK10: 998.89546 | AL10: 868.57861 | AM10: 754.22166 | AN10: 654.13667 | AO10: 566.74362 | AP10: 490.58436 | AQ10: 424.32851 | AR10: 366.77345 | AS10: 316.84031 | AT10: 273.56737 | AU10: 236.10182 | AV10: 203.6908 | AW10: 175.67214 | AX10: 151.46529 | AY10: 130.5626 | AZ10: 112.52119 | BA10: 96.955442 | BB10: 83.530125 | BC10: 71.954243 | BD10: 61.975497 | BE10: 53.375363 | BF10: 45.964741 | BG10: 39.580116 | BH10: 34.080188 | BI10: 29.342923 | BJ10: 25.262976 | BK10: 21.749447 | BL10: 18.723925 | BM10: 16.118798 | BN10: 13.875776 | BO10: 11.94462 | BP10: 10.282037 | BQ10: 8.850725 | BR10: 7.6185521 | BS10: 6.5578395 | BT10: 5.6447484 | BU10: 4.8587494 | BV10: 4.182164 | BW10: 3.5997698 | BX10: 3.0984602 | BY10: 2.6669506
